Workbook

Sheet Constants
A1: Constant | B1: Value
A2: g (m/s2) | B2: 9.81
A3: rho_w (kg/m3) | B3: 1000
A4: rho_s (kg/m3) | B4: 2650
A5: h, flow depth (m) | B5: 0.5
A6: B, bed width (m) | B6: 50
A7: n, Manning | B7: 0.05
A8: D50 (m) | B8: 0.02
A9: Fs, sand fraction | B9: 0.1
A10: phi break | B10: 1.35
A11: Seconds per year (365.25 d) | B11: 31557600
A12: s = rho_s / rho_w | B12: =B4/B3
A13: tau_rm* = 0.021 + 0.015 exp(-20 Fs) | B13: =0.021+0.015*EXP(-20*B9)
A14: Mass factor rho_s / 1000 (t/m3) | B14: =B4/1000

Sheet W star
A1: phi | B1: W* (published) | C1: Low branch 0.002 phi^7.5 | D1: High branch 14 (1 - 0.894/sqrt(phi))^4.5
A2: 0 | B2: =IF(A2<=0,0,IF(A2<Constants!$B$10,C2,D2)) | C2: =0.002*A2^7.5 | D2: =IF(A2>0,14*(1-0.894/SQRT(A2))^4.5,0)
A3: 0.1 | B3: =IF(A3<=0,0,IF(A3<Constants!$B$10,C3,D3)) | C3: =0.002*A3^7.5 | D3: =IF(A3>0,14*(1-0.894/SQRT(A3))^4.5,0)
A4: 0.5 | B4: =IF(A4<=0,0,IF(A4<Constants!$B$10,C4,D4)) | C4: =0.002*A4^7.5 | D4: =IF(A4>0,14*(1-0.894/SQRT(A4))^4.5,0)
A5: 1 | B5: =IF(A5<=0,0,IF(A5<Constants!$B$10,C5,D5)) | C5: =0.002*A5^7.5 | D5: =IF(A5>0,14*(1-0.894/SQRT(A5))^4.5,0)
A6: 1.3 | B6: =IF(A6<=0,0,IF(A6<Constants!$B$10,C6,D6)) | C6: =0.002*A6^7.5 | D6: =IF(A6>0,14*(1-0.894/SQRT(A6))^4.5,0)
A7: 1.35 | B7: =IF(A7<=0,0,IF(A7<Constants!$B$10,C7,D7)) | C7: =0.002*A7^7.5 | D7: =IF(A7>0,14*(1-0.894/SQRT(A7))^4.5,0)
A8: 1.5 | B8: =IF(A8<=0,0,IF(A8<Constants!$B$10,C8,D8)) | C8: =0.002*A8^7.5 | D8: =IF(A8>0,14*(1-0.894/SQRT(A8))^4.5,0)
A9: 2 | B9: =IF(A9<=0,0,IF(A9<Constants!$B$10,C9,D9)) | C9: =0.002*A9^7.5 | D9: =IF(A9>0,14*(1-0.894/SQRT(A9))^4.5,0)
A10: 4 | B10: =IF(A10<=0,0,IF(A10<Constants!$B$10,C10,D10)) | C10: =0.002*A10^7.5 | D10: =IF(A10>0,14*(1-0.894/SQRT(A10))^4.5,0)
A11: 10 | B11: =IF(A11<=0,0,IF(A11<Constants!$B$10,C11,D11)) | C11: =0.002*A11^7.5 | D11: =IF(A11>0,14*(1-0.894/SQRT(A11))^4.5,0)

Sheet Fractions
A1: di (m) | B1: Fi | C1: di / D50 | D1: b_i = 0.67 / (1 + exp(1.5 - di/D50)) | E1: tau_ri* = tau_rm* (di/D50)^b_i | F1: tau_ri = tau_ri* (s-1) rho_w g di (Pa) | H1: Rows without Fi only check tau_ri.
A2: 0.004 | B2: 0.1 | C2: =A2/Constants!$B$8 | D2: =0.67/(1+EXP(1.5-C2)) | E2: =Constants!$B$13*C2^D2 | F2: =E2*(Constants!$B$12-1)*Constants!$B$3*Constants!$B$2*A2
A3: 0.01 | B3: 0.2 | C3: =A3/Constants!$B$8 | D3: =0.67/(1+EXP(1.5-C3)) | E3: =Constants!$B$13*C3^D3 | F3: =E3*(Constants!$B$12-1)*Constants!$B$3*Constants!$B$2*A3
A4: 0.02 | B4: 0.35 | C4: =A4/Constants!$B$8 | D4: =0.67/(1+EXP(1.5-C4)) | E4: =Constants!$B$13*C4^D4 | F4: =E4*(Constants!$B$12-1)*Constants!$B$3*Constants!$B$2*A4
A5: 0.032 | B5: 0.25 | C5: =A5/Constants!$B$8 | D5: =0.67/(1+EXP(1.5-C5)) | E5: =Constants!$B$13*C5^D5 | F5: =E5*(Constants!$B$12-1)*Constants!$B$3*Constants!$B$2*A5
A6: 0.05 | B6: 0.1 | C6: =A6/Constants!$B$8 | D6: =0.67/(1+EXP(1.5-C6)) | E6: =Constants!$B$13*C6^D6 | F6: =E6*(Constants!$B$12-1)*Constants!$B$3*Constants!$B$2*A6
A7: 0.001 | C7: =A7/Constants!$B$8 | D7: =0.67/(1+EXP(1.5-C7)) | E7: =Constants!$B$13*C7^D7 | F7: =E7*(Constants!$B$12-1)*Constants!$B$3*Constants!$B$2*A7
A8: 0.1 | C8: =A8/Constants!$B$8 | D8: =0.67/(1+EXP(1.5-C8)) | E8: =Constants!$B$13*C8^D8 | F8: =E8*(Constants!$B$12-1)*Constants!$B$3*Constants!$B$2*A8

Sheet Transport
A1: Q (m3/s) | B1: di (m) | C1: Fi | D1: v = Q / (B h) | E1: tau = rho_w g n^2 v^2 / h^(1/3) (Pa) | F1: u* = sqrt(tau / rho_w) | G1: tau_ri (Pa) | H1: phi = tau / tau_ri | I1: W* | J1: q_bi = W* Fi u*^3 / ((s-1) g) | L1: Q (m3/s) | M1: q_b = sum of q_bi (m2/s)
A2: 0 | B2: =Fractions!$A$2 | C2: =Fractions!$B$2 | D2: =A2/(Constants!$B$6*Constants!$B$5) | E2: =Constants!$B$3*Constants!$B$2*Constants!$B$7^2*D2^2/Constants!$B$5^(1/3) | F2: =SQRT(E2/Constants!$B$3) | G2: =Fractions!$F$2 | H2: =E2/G2 | I2: =IF(H2<=0,0,IF(H2<Constants!$B$10,0.002*H2^7.5,14*(1-0.894/SQRT(H2))^4.5)) | J2: =I2*C2*F2^3/((Constants!$B$12-1)*Constants!$B$2) | L2: 0 | M2: =SUMIF($A$2:$A$41,L2,$J$2:$J$41)
A3: 0 | B3: =Fractions!$A$3 | C3: =Fractions!$B$3 | D3: =A3/(Constants!$B$6*Constants!$B$5) | E3: =Constants!$B$3*Constants!$B$2*Constants!$B$7^2*D3^2/Constants!$B$5^(1/3) | F3: =SQRT(E3/Constants!$B$3) | G3: =Fractions!$F$3 | H3: =E3/G3 | I3: =IF(H3<=0,0,IF(H3<Constants!$B$10,0.002*H3^7.5,14*(1-0.894/SQRT(H3))^4.5)) | J3: =I3*C3*F3^3/((Constants!$B$12-1)*Constants!$B$2) | L3: 5 | M3: =SUMIF($A$2:$A$41,L3,$J$2:$J$41)
A4: 0 | B4: =Fractions!$A$4 | C4: =Fractions!$B$4 | D4: =A4/(Constants!$B$6*Constants!$B$5) | E4: =Constants!$B$3*Constants!$B$2*Constants!$B$7^2*D4^2/Constants!$B$5^(1/3) | F4: =SQRT(E4/Constants!$B$3) | G4: =Fractions!$F$4 | H4: =E4/G4 | I4: =IF(H4<=0,0,IF(H4<Constants!$B$10,0.002*H4^7.5,14*(1-0.894/SQRT(H4))^4.5)) | J4: =I4*C4*F4^3/((Constants!$B$12-1)*Constants!$B$2) | L4: 10 | M4: =SUMIF($A$2:$A$41,L4,$J$2:$J$41)
A5: 0 | B5: =Fractions!$A$5 | C5: =Fractions!$B$5 | D5: =A5/(Constants!$B$6*Constants!$B$5) | E5: =Constants!$B$3*Constants!$B$2*Constants!$B$7^2*D5^2/Constants!$B$5^(1/3) | F5: =SQRT(E5/Constants!$B$3) | G5: =Fractions!$F$5 | H5: =E5/G5 | I5: =IF(H5<=0,0,IF(H5<Constants!$B$10,0.002*H5^7.5,14*(1-0.894/SQRT(H5))^4.5)) | J5: =I5*C5*F5^3/((Constants!$B$12-1)*Constants!$B$2) | L5: 12.5 | M5: =SUMIF($A$2:$A$41,L5,$J$2:$J$41)
A6: 0 | B6: =Fractions!$A$6 | C6: =Fractions!$B$6 | D6: =A6/(Constants!$B$6*Constants!$B$5) | E6: =Constants!$B$3*Constants!$B$2*Constants!$B$7^2*D6^2/Constants!$B$5^(1/3) | F6: =SQRT(E6/Constants!$B$3) | G6: =Fractions!$F$6 | H6: =E6/G6 | I6: =IF(H6<=0,0,IF(H6<Constants!$B$10,0.002*H6^7.5,14*(1-0.894/SQRT(H6))^4.5)) | J6: =I6*C6*F6^3/((Constants!$B$12-1)*Constants!$B$2) | L6: 15 | M6: =SUMIF($A$2:$A$41,L6,$J$2:$J$41)
A7: 5 | B7: =Fractions!$A$2 | C7: =Fractions!$B$2 | D7: =A7/(Constants!$B$6*Constants!$B$5) | E7: =Constants!$B$3*Constants!$B$2*Constants!$B$7^2*D7^2/Constants!$B$5^(1/3) | F7: =SQRT(E7/Constants!$B$3) | G7: =Fractions!$F$2 | H7: =E7/G7 | I7: =IF(H7<=0,0,IF(H7<Constants!$B$10,0.002*H7^7.5,14*(1-0.894/SQRT(H7))^4.5)) | J7: =I7*C7*F7^3/((Constants!$B$12-1)*Constants!$B$2) | L7: 25 | M7: =SUMIF($A$2:$A$41,L7,$J$2:$J$41)
A8: 5 | B8: =Fractions!$A$3 | C8: =Fractions!$B$3 | D8: =A8/(Constants!$B$6*Constants!$B$5) | E8: =Constants!$B$3*Constants!$B$2*Constants!$B$7^2*D8^2/Constants!$B$5^(1/3) | F8: =SQRT(E8/Constants!$B$3) | G8: =Fractions!$F$3 | H8: =E8/G8 | I8: =IF(H8<=0,0,IF(H8<Constants!$B$10,0.002*H8^7.5,14*(1-0.894/SQRT(H8))^4.5)) | J8: =I8*C8*F8^3/((Constants!$B$12-1)*Constants!$B$2) | L8: 50 | M8: =SUMIF($A$2:$A$41,L8,$J$2:$J$41)
A9: 5 | B9: =Fractions!$A$4 | C9: =Fractions!$B$4 | D9: =A9/(Constants!$B$6*Constants!$B$5) | E9: =Constants!$B$3*Constants!$B$2*Constants!$B$7^2*D9^2/Constants!$B$5^(1/3) | F9: =SQRT(E9/Constants!$B$3) | G9: =Fractions!$F$4 | H9: =E9/G9 | I9: =IF(H9<=0,0,IF(H9<Constants!$B$10,0.002*H9^7.5,14*(1-0.894/SQRT(H9))^4.5)) | J9: =I9*C9*F9^3/((Constants!$B$12-1)*Constants!$B$2) | L9: 100 | M9: =SUMIF($A$2:$A$41,L9,$J$2:$J$41)
A10: 5 | B10: =Fractions!$A$5 | C10: =Fractions!$B$5 | D10: =A10/(Constants!$B$6*Constants!$B$5) | E10: =Constants!$B$3*Constants!$B$2*Constants!$B$7^2*D10^2/Constants!$B$5^(1/3) | F10: =SQRT(E10/Constants!$B$3) | G10: =Fractions!$F$5 | H10: =E10/G10 | I10: =IF(H10<=0,0,IF(H10<Constants!$B$10,0.002*H10^7.5,14*(1-0.894/SQRT(H10))^4.5)) | J10: =I10*C10*F10^3/((Constants!$B$12-1)*Constants!$B$2)
A11: 5 | B11: =Fractions!$A$6 | C11: =Fractions!$B$6 | D11: =A11/(Constants!$B$6*Constants!$B$5) | E11: =Constants!$B$3*Constants!$B$2*Constants!$B$7^2*D11^2/Constants!$B$5^(1/3) | F11: =SQRT(E11/Constants!$B$3) | G11: =Fractions!$F$6 | H11: =E11/G11 | I11: =IF(H11<=0,0,IF(H11<Constants!$B$10,0.002*H11^7.5,14*(1-0.894/SQRT(H11))^4.5)) | J11: =I11*C11*F11^3/((Constants!$B$12-1)*Constants!$B$2)
A12: 10 | B12: =Fractions!$A$2 | C12: =Fractions!$B$2 | D12: =A12/(Constants!$B$6*Constants!$B$5) | E12: =Constants!$B$3*Constants!$B$2*Constants!$B$7^2*D12^2/Constants!$B$5^(1/3) | F12: =SQRT(E12/Constants!$B$3) | G12: =Fractions!$F$2 | H12: =E12/G12 | I12: =IF(H12<=0,0,IF(H12<Constants!$B$10,0.002*H12^7.5,14*(1-0.894/SQRT(H12))^4.5)) | J12: =I12*C12*F12^3/((Constants!$B$12-1)*Constants!$B$2)
A13: 10 | B13: =Fractions!$A$3 | C13: =Fractions!$B$3 | D13: =A13/(Constants!$B$6*Constants!$B$5) | E13: =Constants!$B$3*Constants!$B$2*Constants!$B$7^2*D13^2/Constants!$B$5^(1/3) | F13: =SQRT(E13/Constants!$B$3) | G13: =Fractions!$F$3 | H13: =E13/G13 | I13: =IF(H13<=0,0,IF(H13<Constants!$B$10,0.002*H13^7.5,14*(1-0.894/SQRT(H13))^4.5)) | J13: =I13*C13*F13^3/((Constants!$B$12-1)*Constants!$B$2)
A14: 10 | B14: =Fractions!$A$4 | C14: =Fractions!$B$4 | D14: =A14/(Constants!$B$6*Constants!$B$5) | E14: =Constants!$B$3*Constants!$B$2*Constants!$B$7^2*D14^2/Constants!$B$5^(1/3) | F14: =SQRT(E14/Constants!$B$3) | G14: =Fractions!$F$4 | H14: =E14/G14 | I14: =IF(H14<=0,0,IF(H14<Constants!$B$10,0.002*H14^7.5,14*(1-0.894/SQRT(H14))^4.5)) | J14: =I14*C14*F14^3/((Constants!$B$12-1)*Constants!$B$2)
A15: 10 | B15: =Fractions!$A$5 | C15: =Fractions!$B$5 | D15: =A15/(Constants!$B$6*Constants!$B$5) | E15: =Constants!$B$3*Constants!$B$2*Constants!$B$7^2*D15^2/Constants!$B$5^(1/3) | F15: =SQRT(E15/Constants!$B$3) | G15: =Fractions!$F$5 | H15: =E15/G15 | I15: =IF(H15<=0,0,IF(H15<Constants!$B$10,0.002*H15^7.5,14*(1-0.894/SQRT(H15))^4.5)) | J15: =I15*C15*F15^3/((Constants!$B$12-1)*Constants!$B$2)
A16: 10 | B16: =Fractions!$A$6 | C16: =Fractions!$B$6 | D16: =A16/(Constants!$B$6*Constants!$B$5) | E16: =Constants!$B$3*Constants!$B$2*Constants!$B$7^2*D16^2/Constants!$B$5^(1/3) | F16: =SQRT(E16/Constants!$B$3) | G16: =Fractions!$F$6 | H16: =E16/G16 | I16: =IF(H16<=0,0,IF(H16<Constants!$B$10,0.002*H16^7.5,14*(1-0.894/SQRT(H16))^4.5)) | J16: =I16*C16*F16^3/((Constants!$B$12-1)*Constants!$B$2)
A17: 12.5 | B17: =Fractions!$A$2 | C17: =Fractions!$B$2 | D17: =A17/(Constants!$B$6*Constants!$B$5) | E17: =Constants!$B$3*Constants!$B$2*Constants!$B$7^2*D17^2/Constants!$B$5^(1/3) | F17: =SQRT(E17/Constants!$B$3) | G17: =Fractions!$F$2 | H17: =E17/G17 | I17: =IF(H17<=0,0,IF(H17<Constants!$B$10,0.002*H17^7.5,14*(1-0.894/SQRT(H17))^4.5)) | J17: =I17*C17*F17^3/((Constants!$B$12-1)*Constants!$B$2)
A18: 12.5 | B18: =Fractions!$A$3 | C18: =Fractions!$B$3 | D18: =A18/(Constants!$B$6*Constants!$B$5) | E18: =Constants!$B$3*Constants!$B$2*Constants!$B$7^2*D18^2/Constants!$B$5^(1/3) | F18: =SQRT(E18/Constants!$B$3) | G18: =Fractions!$F$3 | H18: =E18/G18 | I18: =IF(H18<=0,0,IF(H18<Constants!$B$10,0.002*H18^7.5,14*(1-0.894/SQRT(H18))^4.5)) | J18: =I18*C18*F18^3/((Constants!$B$12-1)*Constants!$B$2)
A19: 12.5 | B19: =Fractions!$A$4 | C19: =Fractions!$B$4 | D19: =A19/(Constants!$B$6*Constants!$B$5) | E19: =Constants!$B$3*Constants!$B$2*Constants!$B$7^2*D19^2/Constants!$B$5^(1/3) | F19: =SQRT(E19/Constants!$B$3) | G19: =Fractions!$F$4 | H19: =E19/G19 | I19: =IF(H19<=0,0,IF(H19<Constants!$B$10,0.002*H19^7.5,14*(1-0.894/SQRT(H19))^4.5)) | J19: =I19*C19*F19^3/((Constants!$B$12-1)*Constants!$B$2)
A20: 12.5 | B20: =Fractions!$A$5 | C20: =Fractions!$B$5 | D20: =A20/(Constants!$B$6*Constants!$B$5) | E20: =Constants!$B$3*Constants!$B$2*Constants!$B$7^2*D20^2/Constants!$B$5^(1/3) | F20: =SQRT(E20/Constants!$B$3) | G20: =Fractions!$F$5 | H20: =E20/G20 | I20: =IF(H20<=0,0,IF(H20<Constants!$B$10,0.002*H20^7.5,14*(1-0.894/SQRT(H20))^4.5)) | J20: =I20*C20*F20^3/((Constants!$B$12-1)*Constants!$B$2)
A21: 12.5 | B21: =Fractions!$A$6 | C21: =Fractions!$B$6 | D21: =A21/(Constants!$B$6*Constants!$B$5) | E21: =Constants!$B$3*Constants!$B$2*Constants!$B$7^2*D21^2/Constants!$B$5^(1/3) | F21: =SQRT(E21/Constants!$B$3) | G21: =Fractions!$F$6 | H21: =E21/G21 | I21: =IF(H21<=0,0,IF(H21<Constants!$B$10,0.002*H21^7.5,14*(1-0.894/SQRT(H21))^4.5)) | J21: =I21*C21*F21^3/((Constants!$B$12-1)*Constants!$B$2)
A22: 15 | B22: =Fractions!$A$2 | C22: =Fractions!$B$2 | D22: =A22/(Constants!$B$6*Constants!$B$5) | E22: =Constants!$B$3*Constants!$B$2*Constants!$B$7^2*D22^2/Constants!$B$5^(1/3) | F22: =SQRT(E22/Constants!$B$3) | G22: =Fractions!$F$2 | H22: =E22/G22 | I22: =IF(H22<=0,0,IF(H22<Constants!$B$10,0.002*H22^7.5,14*(1-0.894/SQRT(H22))^4.5)) | J22: =I22*C22*F22^3/((Constants!$B$12-1)*Constants!$B$2)
A23: 15 | B23: =Fractions!$A$3 | C23: =Fractions!$B$3 | D23: =A23/(Constants!$B$6*Constants!$B$5) | E23: =Constants!$B$3*Constants!$B$2*Constants!$B$7^2*D23^2/Constants!$B$5^(1/3) | F23: =SQRT(E23/Constants!$B$3) | G23: =Fractions!$F$3 | H23: =E23/G23 | I23: =IF(H23<=0,0,IF(H23<Constants!$B$10,0.002*H23^7.5,14*(1-0.894/SQRT(H23))^4.5)) | J23: =I23*C23*F23^3/((Constants!$B$12-1)*Constants!$B$2)
A24: 15 | B24: =Fractions!$A$4 | C24: =Fractions!$B$4 | D24: =A24/(Constants!$B$6*Constants!$B$5) | E24: =Constants!$B$3*Constants!$B$2*Constants!$B$7^2*D24^2/Constants!$B$5^(1/3) | F24: =SQRT(E24/Constants!$B$3) | G24: =Fractions!$F$4 | H24: =E24/G24 | I24: =IF(H24<=0,0,IF(H24<Constants!$B$10,0.002*H24^7.5,14*(1-0.894/SQRT(H24))^4.5)) | J24: =I24*C24*F24^3/((Constants!$B$12-1)*Constants!$B$2)
A25: 15 | B25: =Fractions!$A$5 | C25: =Fractions!$B$5 | D25: =A25/(Constants!$B$6*Constants!$B$5) | E25: =Constants!$B$3*Constants!$B$2*Constants!$B$7^2*D25^2/Constants!$B$5^(1/3) | F25: =SQRT(E25/Constants!$B$3) | G25: =Fractions!$F$5 | H25: =E25/G25 | I25: =IF(H25<=0,0,IF(H25<Constants!$B$10,0.002*H25^7.5,14*(1-0.894/SQRT(H25))^4.5)) | J25: =I25*C25*F25^3/((Constants!$B$12-1)*Constants!$B$2)
A26: 15 | B26: =Fractions!$A$6 | C26: =Fractions!$B$6 | D26: =A26/(Constants!$B$6*Constants!$B$5) | E26: =Constants!$B$3*Constants!$B$2*Constants!$B$7^2*D26^2/Constants!$B$5^(1/3) | F26: =SQRT(E26/Constants!$B$3) | G26: =Fractions!$F$6 | H26: =E26/G26 | I26: =IF(H26<=0,0,IF(H26<Constants!$B$10,0.002*H26^7.5,14*(1-0.894/SQRT(H26))^4.5)) | J26: =I26*C26*F26^3/((Constants!$B$12-1)*Constants!$B$2)
A27: 25 | B27: =Fractions!$A$2 | C27: =Fractions!$B$2 | D27: =A27/(Constants!$B$6*Constants!$B$5) | E27: =Constants!$B$3*Constants!$B$2*Constants!$B$7^2*D27^2/Constants!$B$5^(1/3) | F27: =SQRT(E27/Constants!$B$3) | G27: =Fractions!$F$2 | H27: =E27/G27 | I27: =IF(H27<=0,0,IF(H27<Constants!$B$10,0.002*H27^7.5,14*(1-0.894/SQRT(H27))^4.5)) | J27: =I27*C27*F27^3/((Constants!$B$12-1)*Constants!$B$2)
A28: 25 | B28: =Fractions!$A$3 | C28: =Fractions!$B$3 | D28: =A28/(Constants!$B$6*Constants!$B$5) | E28: =Constants!$B$3*Constants!$B$2*Constants!$B$7^2*D28^2/Constants!$B$5^(1/3) | F28: =SQRT(E28/Constants!$B$3) | G28: =Fractions!$F$3 | H28: =E28/G28 | I28: =IF(H28<=0,0,IF(H28<Constants!$B$10,0.002*H28^7.5,14*(1-0.894/SQRT(H28))^4.5)) | J28: =I28*C28*F28^3/((Constants!$B$12-1)*Constants!$B$2)
A29: 25 | B29: =Fractions!$A$4 | C29: =Fractions!$B$4 | D29: =A29/(Constants!$B$6*Constants!$B$5) | E29: =Constants!$B$3*Constants!$B$2*Constants!$B$7^2*D29^2/Constants!$B$5^(1/3) | F29: =SQRT(E29/Constants!$B$3) | G29: =Fractions!$F$4 | H29: =E29/G29 | I29: =IF(H29<=0,0,IF(H29<Constants!$B$10,0.002*H29^7.5,14*(1-0.894/SQRT(H29))^4.5)) | J29: =I29*C29*F29^3/((Constants!$B$12-1)*Constants!$B$2)
A30: 25 | B30: =Fractions!$A$5 | C30: =Fractions!$B$5 | D30: =A30/(Constants!$B$6*Constants!$B$5) | E30: =Constants!$B$3*Constants!$B$2*Constants!$B$7^2*D30^2/Constants!$B$5^(1/3) | F30: =SQRT(E30/Constants!$B$3) | G30: =Fractions!$F$5 | H30: =E30/G30 | I30: =IF(H30<=0,0,IF(H30<Constants!$B$10,0.002*H30^7.5,14*(1-0.894/SQRT(H30))^4.5)) | J30: =I30*C30*F30^3/((Constants!$B$12-1)*Constants!$B$2)
A31: 25 | B31: =Fractions!$A$6 | C31: =Fractions!$B$6 | D31: =A31/(Constants!$B$6*Constants!$B$5) | E31: =Constants!$B$3*Constants!$B$2*Constants!$B$7^2*D31^2/Constants!$B$5^(1/3) | F31: =SQRT(E31/Constants!$B$3) | G31: =Fractions!$F$6 | H31: =E31/G31 | I31: =IF(H31<=0,0,IF(H31<Constants!$B$10,0.002*H31^7.5,14*(1-0.894/SQRT(H31))^4.5)) | J31: =I31*C31*F31^3/((Constants!$B$12-1)*Constants!$B$2)
A32: 50 | B32: =Fractions!$A$2 | C32: =Fractions!$B$2 | D32: =A32/(Constants!$B$6*Constants!$B$5) | E32: =Constants!$B$3*Constants!$B$2*Constants!$B$7^2*D32^2/Constants!$B$5^(1/3) | F32: =SQRT(E32/Constants!$B$3) | G32: =Fractions!$F$2 | H32: =E32/G32 | I32: =IF(H32<=0,0,IF(H32<Constants!$B$10,0.002*H32^7.5,14*(1-0.894/SQRT(H32))^4.5)) | J32: =I32*C32*F32^3/((Constants!$B$12-1)*Constants!$B$2)
A33: 50 | B33: =Fractions!$A$3 | C33: =Fractions!$B$3 | D33: =A33/(Constants!$B$6*Constants!$B$5) | E33: =Constants!$B$3*Constants!$B$2*Constants!$B$7^2*D33^2/Constants!$B$5^(1/3) | F33: =SQRT(E33/Constants!$B$3) | G33: =Fractions!$F$3 | H33: =E33/G33 | I33: =IF(H33<=0,0,IF(H33<Constants!$B$10,0.002*H33^7.5,14*(1-0.894/SQRT(H33))^4.5)) | J33: =I33*C33*F33^3/((Constants!$B$12-1)*Constants!$B$2)
A34: 50 | B34: =Fractions!$A$4 | C34: =Fractions!$B$4 | D34: =A34/(Constants!$B$6*Constants!$B$5) | E34: =Constants!$B$3*Constants!$B$2*Constants!$B$7^2*D34^2/Constants!$B$5^(1/3) | F34: =SQRT(E34/Constants!$B$3) | G34: =Fractions!$F$4 | H34: =E34/G34 | I34: =IF(H34<=0,0,IF(H34<Constants!$B$10,0.002*H34^7.5,14*(1-0.894/SQRT(H34))^4.5)) | J34: =I34*C34*F34^3/((Constants!$B$12-1)*Constants!$B$2)
A35: 50 | B35: =Fractions!$A$5 | C35: =Fractions!$B$5 | D35: =A35/(Constants!$B$6*Constants!$B$5) | E35: =Constants!$B$3*Constants!$B$2*Constants!$B$7^2*D35^2/Constants!$B$5^(1/3) | F35: =SQRT(E35/Constants!$B$3) | G35: =Fractions!$F$5 | H35: =E35/G35 | I35: =IF(H35<=0,0,IF(H35<Constants!$B$10,0.002*H35^7.5,14*(1-0.894/SQRT(H35))^4.5)) | J35: =I35*C35*F35^3/((Constants!$B$12-1)*Constants!$B$2)
A36: 50 | B36: =Fractions!$A$6 | C36: =Fractions!$B$6 | D36: =A36/(Constants!$B$6*Constants!$B$5) | E36: =Constants!$B$3*Constants!$B$2*Constants!$B$7^2*D36^2/Constants!$B$5^(1/3) | F36: =SQRT(E36/Constants!$B$3) | G36: =Fractions!$F$6 | H36: =E36/G36 | I36: =IF(H36<=0,0,IF(H36<Constants!$B$10,0.002*H36^7.5,14*(1-0.894/SQRT(H36))^4.5)) | J36: =I36*C36*F36^3/((Constants!$B$12-1)*Constants!$B$2)
A37: 100 | B37: =Fractions!$A$2 | C37: =Fractions!$B$2 | D37: =A37/(Constants!$B$6*Constants!$B$5) | E37: =Constants!$B$3*Constants!$B$2*Constants!$B$7^2*D37^2/Constants!$B$5^(1/3) | F37: =SQRT(E37/Constants!$B$3) | G37: =Fractions!$F$2 | H37: =E37/G37 | I37: =IF(H37<=0,0,IF(H37<Constants!$B$10,0.002*H37^7.5,14*(1-0.894/SQRT(H37))^4.5)) | J37: =I37*C37*F37^3/((Constants!$B$12-1)*Constants!$B$2)
A38: 100 | B38: =Fractions!$A$3 | C38: =Fractions!$B$3 | D38: =A38/(Constants!$B$6*Constants!$B$5) | E38: =Constants!$B$3*Constants!$B$2*Constants!$B$7^2*D38^2/Constants!$B$5^(1/3) | F38: =SQRT(E38/Constants!$B$3) | G38: =Fractions!$F$3 | H38: =E38/G38 | I38: =IF(H38<=0,0,IF(H38<Constants!$B$10,0.002*H38^7.5,14*(1-0.894/SQRT(H38))^4.5)) | J38: =I38*C38*F38^3/((Constants!$B$12-1)*Constants!$B$2)
A39: 100 | B39: =Fractions!$A$4 | C39: =Fractions!$B$4 | D39: =A39/(Constants!$B$6*Constants!$B$5) | E39: =Constants!$B$3*Constants!$B$2*Constants!$B$7^2*D39^2/Constants!$B$5^(1/3) | F39: =SQRT(E39/Constants!$B$3) | G39: =Fractions!$F$4 | H39: =E39/G39 | I39: =IF(H39<=0,0,IF(H39<Constants!$B$10,0.002*H39^7.5,14*(1-0.894/SQRT(H39))^4.5)) | J39: =I39*C39*F39^3/((Constants!$B$12-1)*Constants!$B$2)
A40: 100 | B40: =Fractions!$A$5 | C40: =Fractions!$B$5 | D40: =A40/(Constants!$B$6*Constants!$B$5) | E40: =Constants!$B$3*Constants!$B$2*Constants!$B$7^2*D40^2/Constants!$B$5^(1/3) | F40: =SQRT(E40/Constants!$B$3) | G40: =Fractions!$F$5 | H40: =E40/G40 | I40: =IF(H40<=0,0,IF(H40<Constants!$B$10,0.002*H40^7.5,14*(1-0.894/SQRT(H40))^4.5)) | J40: =I40*C40*F40^3/((Constants!$B$12-1)*Constants!$B$2)
...

Sheet Annual
A1: Date | B1: Q (m3/s) | C1: Water_Year | D1: v | E1: tau (Pa) | F1: u* (m/s) | G1: q_b fraction 1 (m2/s) | H1: q_b fraction 2 (m2/s) | I1: q_b fraction 3 (m2/s) | J1: q_b fraction 4 (m2/s) | K1: q_b fraction 5 (m2/s) | L1: q_b daily (m2/s) | M1: Calendar year | O1: Grouping | P1: Key | Q1: Mean Q (m3/s) | R1: Mean q_b (m2/s) | S1: Volume V_b = q_b B s/yr (m3/yr) | T1: Mass M_b (t/yr)
A2: 40086 | B2: 12 | C2: =IF(MONTH(A2)>=10,YEAR(A2)+1,YEAR(A2)) | D2: =B2/(Constants!$B$6*Constants!$B$5) | E2: =Constants!$B$3*Constants!$B$2*Constants!$B$7^2*D2^2/Constants!$B$5^(1/3) | F2: =SQRT(E2/Constants!$B$3) | G2: =IF(E2<=0,0,IF(E2/Fractions!$F$2<Constants!$B$10,0.002*(E2/Fractions!$F$2)^7.5,14*(1-0.894/SQRT(E2/Fractions!$F$2))^4.5))*Fractions!$B$2*F2^3/((Constants!$B$12-1)*Constants!$B$2) | H2: =IF(E2<=0,0,IF(E2/Fractions!$F$3<Constants!$B$10,0.002*(E2/Fractions!$F$3)^7.5,14*(1-0.894/SQRT(E2/Fractions!$F$3))^4.5))*Fractions!$B$3*F2^3/((Constants!$B$12-1)*Constants!$B$2) | I2: =IF(E2<=0,0,IF(E2/Fractions!$F$4<Constants!$B$10,0.002*(E2/Fractions!$F$4)^7.5,14*(1-0.894/SQRT(E2/Fractions!$F$4))^4.5))*Fractions!$B$4*F2^3/((Constants!$B$12-1)*Constants!$B$2) | J2: =IF(E2<=0,0,IF(E2/Fractions!$F$5<Constants!$B$10,0.002*(E2/Fractions!$F$5)^7.5,14*(1-0.894/SQRT(E2/Fractions!$F$5))^4.5))*Fractions!$B$5*F2^3/((Constants!$B$12-1)*Constants!$B$2) | K2: =IF(E2<=0,0,IF(E2/Fractions!$F$6<Constants!$B$10,0.002*(E2/Fractions!$F$6)^7.5,14*(1-0.894/SQRT(E2/Fractions!$F$6))^4.5))*Fractions!$B$6*F2^3/((Constants!$B$12-1)*Constants!$B$2) | L2: =SUM(G2:K2) | M2: =YEAR(A2) | O2: calendar | P2: 2009 | Q2: =AVERAGEIF($M$2:$M$9,P2,$B$2:$B$9) | R2: =AVERAGEIF($M$2:$M$9,P2,$L$2:$L$9) | S2: =R2*Constants!$B$6*Constants!$B$11 | T2: =S2*Constants!$B$14
A3: 40087 | B3: 18.5 | C3: =IF(MONTH(A3)>=10,YEAR(A3)+1,YEAR(A3)) | D3: =B3/(Constants!$B$6*Constants!$B$5) | E3: =Constants!$B$3*Constants!$B$2*Constants!$B$7^2*D3^2/Constants!$B$5^(1/3) | F3: =SQRT(E3/Constants!$B$3) | G3: =IF(E3<=0,0,IF(E3/Fractions!$F$2<Constants!$B$10,0.002*(E3/Fractions!$F$2)^7.5,14*(1-0.894/SQRT(E3/Fractions!$F$2))^4.5))*Fractions!$B$2*F3^3/((Constants!$B$12-1)*Constants!$B$2) | H3: =IF(E3<=0,0,IF(E3/Fractions!$F$3<Constants!$B$10,0.002*(E3/Fractions!$F$3)^7.5,14*(1-0.894/SQRT(E3/Fractions!$F$3))^4.5))*Fractions!$B$3*F3^3/((Constants!$B$12-1)*Constants!$B$2) | I3: =IF(E3<=0,0,IF(E3/Fractions!$F$4<Constants!$B$10,0.002*(E3/Fractions!$F$4)^7.5,14*(1-0.894/SQRT(E3/Fractions!$F$4))^4.5))*Fractions!$B$4*F3^3/((Constants!$B$12-1)*Constants!$B$2) | J3: =IF(E3<=0,0,IF(E3/Fractions!$F$5<Constants!$B$10,0.002*(E3/Fractions!$F$5)^7.5,14*(1-0.894/SQRT(E3/Fractions!$F$5))^4.5))*Fractions!$B$5*F3^3/((Constants!$B$12-1)*Constants!$B$2) | K3: =IF(E3<=0,0,IF(E3/Fractions!$F$6<Constants!$B$10,0.002*(E3/Fractions!$F$6)^7.5,14*(1-0.894/SQRT(E3/Fractions!$F$6))^4.5))*Fractions!$B$6*F3^3/((Constants!$B$12-1)*Constants!$B$2) | L3: =SUM(G3:K3) | M3: =YEAR(A3) | O3: calendar | P3: 2010 | Q3: =AVERAGEIF($M$2:$M$9,P3,$B$2:$B$9) | R3: =AVERAGEIF($M$2:$M$9,P3,$L$2:$L$9) | S3: =R3*Constants!$B$6*Constants!$B$11 | T3: =S3*Constants!$B$14
A4: 40178 | B4: 0 | C4: =IF(MONTH(A4)>=10,YEAR(A4)+1,YEAR(A4)) | D4: =B4/(Constants!$B$6*Constants!$B$5) | E4: =Constants!$B$3*Constants!$B$2*Constants!$B$7^2*D4^2/Constants!$B$5^(1/3) | F4: =SQRT(E4/Constants!$B$3) | G4: =IF(E4<=0,0,IF(E4/Fractions!$F$2<Constants!$B$10,0.002*(E4/Fractions!$F$2)^7.5,14*(1-0.894/SQRT(E4/Fractions!$F$2))^4.5))*Fractions!$B$2*F4^3/((Constants!$B$12-1)*Constants!$B$2) | H4: =IF(E4<=0,0,IF(E4/Fractions!$F$3<Constants!$B$10,0.002*(E4/Fractions!$F$3)^7.5,14*(1-0.894/SQRT(E4/Fractions!$F$3))^4.5))*Fractions!$B$3*F4^3/((Constants!$B$12-1)*Constants!$B$2) | I4: =IF(E4<=0,0,IF(E4/Fractions!$F$4<Constants!$B$10,0.002*(E4/Fractions!$F$4)^7.5,14*(1-0.894/SQRT(E4/Fractions!$F$4))^4.5))*Fractions!$B$4*F4^3/((Constants!$B$12-1)*Constants!$B$2) | J4: =IF(E4<=0,0,IF(E4/Fractions!$F$5<Constants!$B$10,0.002*(E4/Fractions!$F$5)^7.5,14*(1-0.894/SQRT(E4/Fractions!$F$5))^4.5))*Fractions!$B$5*F4^3/((Constants!$B$12-1)*Constants!$B$2) | K4: =IF(E4<=0,0,IF(E4/Fractions!$F$6<Constants!$B$10,0.002*(E4/Fractions!$F$6)^7.5,14*(1-0.894/SQRT(E4/Fractions!$F$6))^4.5))*Fractions!$B$6*F4^3/((Constants!$B$12-1)*Constants!$B$2) | L4: =SUM(G4:K4) | M4: =YEAR(A4) | O4: water | P4: 2009 | Q4: =AVERAGEIF($C$2:$C$9,P4,$B$2:$B$9) | R4: =AVERAGEIF($C$2:$C$9,P4,$L$2:$L$9) | S4: =R4*Constants!$B$6*Constants!$B$11 | T4: =S4*Constants!$B$14
A5: 40179 | B5: 9.2 | C5: =IF(MONTH(A5)>=10,YEAR(A5)+1,YEAR(A5)) | D5: =B5/(Constants!$B$6*Constants!$B$5) | E5: =Constants!$B$3*Constants!$B$2*Constants!$B$7^2*D5^2/Constants!$B$5^(1/3) | F5: =SQRT(E5/Constants!$B$3) | G5: =IF(E5<=0,0,IF(E5/Fractions!$F$2<Constants!$B$10,0.002*(E5/Fractions!$F$2)^7.5,14*(1-0.894/SQRT(E5/Fractions!$F$2))^4.5))*Fractions!$B$2*F5^3/((Constants!$B$12-1)*Constants!$B$2) | H5: =IF(E5<=0,0,IF(E5/Fractions!$F$3<Constants!$B$10,0.002*(E5/Fractions!$F$3)^7.5,14*(1-0.894/SQRT(E5/Fractions!$F$3))^4.5))*Fractions!$B$3*F5^3/((Constants!$B$12-1)*Constants!$B$2) | I5: =IF(E5<=0,0,IF(E5/Fractions!$F$4<Constants!$B$10,0.002*(E5/Fractions!$F$4)^7.5,14*(1-0.894/SQRT(E5/Fractions!$F$4))^4.5))*Fractions!$B$4*F5^3/((Constants!$B$12-1)*Constants!$B$2) | J5: =IF(E5<=0,0,IF(E5/Fractions!$F$5<Constants!$B$10,0.002*(E5/Fractions!$F$5)^7.5,14*(1-0.894/SQRT(E5/Fractions!$F$5))^4.5))*Fractions!$B$5*F5^3/((Constants!$B$12-1)*Constants!$B$2) | K5: =IF(E5<=0,0,IF(E5/Fractions!$F$6<Constants!$B$10,0.002*(E5/Fractions!$F$6)^7.5,14*(1-0.894/SQRT(E5/Fractions!$F$6))^4.5))*Fractions!$B$6*F5^3/((Constants!$B$12-1)*Constants!$B$2) | L5: =SUM(G5:K5) | M5: =YEAR(A5) | O5: water | P5: 2010 | Q5: =AVERAGEIF($C$2:$C$9,P5,$B$2:$B$9) | R5: =AVERAGEIF($C$2:$C$9,P5,$L$2:$L$9) | S5: =R5*Constants!$B$6*Constants!$B$11 | T5: =S5*Constants!$B$14
A6: 40344 | B6: 25 | C6: =IF(MONTH(A6)>=10,YEAR(A6)+1,YEAR(A6)) | D6: =B6/(Constants!$B$6*Constants!$B$5) | E6: =Constants!$B$3*Constants!$B$2*Constants!$B$7^2*D6^2/Constants!$B$5^(1/3) | F6: =SQRT(E6/Constants!$B$3) | G6: =IF(E6<=0,0,IF(E6/Fractions!$F$2<Constants!$B$10,0.002*(E6/Fractions!$F$2)^7.5,14*(1-0.894/SQRT(E6/Fractions!$F$2))^4.5))*Fractions!$B$2*F6^3/((Constants!$B$12-1)*Constants!$B$2) | H6: =IF(E6<=0,0,IF(E6/Fractions!$F$3<Constants!$B$10,0.002*(E6/Fractions!$F$3)^7.5,14*(1-0.894/SQRT(E6/Fractions!$F$3))^4.5))*Fractions!$B$3*F6^3/((Constants!$B$12-1)*Constants!$B$2) | I6: =IF(E6<=0,0,IF(E6/Fractions!$F$4<Constants!$B$10,0.002*(E6/Fractions!$F$4)^7.5,14*(1-0.894/SQRT(E6/Fractions!$F$4))^4.5))*Fractions!$B$4*F6^3/((Constants!$B$12-1)*Constants!$B$2) | J6: =IF(E6<=0,0,IF(E6/Fractions!$F$5<Constants!$B$10,0.002*(E6/Fractions!$F$5)^7.5,14*(1-0.894/SQRT(E6/Fractions!$F$5))^4.5))*Fractions!$B$5*F6^3/((Constants!$B$12-1)*Constants!$B$2) | K6: =IF(E6<=0,0,IF(E6/Fractions!$F$6<Constants!$B$10,0.002*(E6/Fractions!$F$6)^7.5,14*(1-0.894/SQRT(E6/Fractions!$F$6))^4.5))*Fractions!$B$6*F6^3/((Constants!$B$12-1)*Constants!$B$2) | L6: =SUM(G6:K6) | M6: =YEAR(A6) | O6: water | P6: 2011 | Q6: =AVERAGEIF($C$2:$C$9,P6,$B$2:$B$9) | R6: =AVERAGEIF($C$2:$C$9,P6,$L$2:$L$9) | S6: =R6*Constants!$B$6*Constants!$B$11 | T6: =S6*Constants!$B$14
A7: 40451 | B7: 14.4 | C7: =IF(MONTH(A7)>=10,YEAR(A7)+1,YEAR(A7)) | D7: =B7/(Constants!$B$6*Constants!$B$5) | E7: =Constants!$B$3*Constants!$B$2*Constants!$B$7^2*D7^2/Constants!$B$5^(1/3) | F7: =SQRT(E7/Constants!$B$3) | G7: =IF(E7<=0,0,IF(E7/Fractions!$F$2<Constants!$B$10,0.002*(E7/Fractions!$F$2)^7.5,14*(1-0.894/SQRT(E7/Fractions!$F$2))^4.5))*Fractions!$B$2*F7^3/((Constants!$B$12-1)*Constants!$B$2) | H7: =IF(E7<=0,0,IF(E7/Fractions!$F$3<Constants!$B$10,0.002*(E7/Fractions!$F$3)^7.5,14*(1-0.894/SQRT(E7/Fractions!$F$3))^4.5))*Fractions!$B$3*F7^3/((Constants!$B$12-1)*Constants!$B$2) | I7: =IF(E7<=0,0,IF(E7/Fractions!$F$4<Constants!$B$10,0.002*(E7/Fractions!$F$4)^7.5,14*(1-0.894/SQRT(E7/Fractions!$F$4))^4.5))*Fractions!$B$4*F7^3/((Constants!$B$12-1)*Constants!$B$2) | J7: =IF(E7<=0,0,IF(E7/Fractions!$F$5<Constants!$B$10,0.002*(E7/Fractions!$F$5)^7.5,14*(1-0.894/SQRT(E7/Fractions!$F$5))^4.5))*Fractions!$B$5*F7^3/((Constants!$B$12-1)*Constants!$B$2) | K7: =IF(E7<=0,0,IF(E7/Fractions!$F$6<Constants!$B$10,0.002*(E7/Fractions!$F$6)^7.5,14*(1-0.894/SQRT(E7/Fractions!$F$6))^4.5))*Fractions!$B$6*F7^3/((Constants!$B$12-1)*Constants!$B$2) | L7: =SUM(G7:K7) | M7: =YEAR(A7)
A8: 40452 | B8: 31 | C8: =IF(MONTH(A8)>=10,YEAR(A8)+1,YEAR(A8)) | D8: =B8/(Constants!$B$6*Constants!$B$5) | E8: =Constants!$B$3*Constants!$B$2*Constants!$B$7^2*D8^2/Constants!$B$5^(1/3) | F8: =SQRT(E8/Constants!$B$3) | G8: =IF(E8<=0,0,IF(E8/Fractions!$F$2<Constants!$B$10,0.002*(E8/Fractions!$F$2)^7.5,14*(1-0.894/SQRT(E8/Fractions!$F$2))^4.5))*Fractions!$B$2*F8^3/((Constants!$B$12-1)*Constants!$B$2) | H8: =IF(E8<=0,0,IF(E8/Fractions!$F$3<Constants!$B$10,0.002*(E8/Fractions!$F$3)^7.5,14*(1-0.894/SQRT(E8/Fractions!$F$3))^4.5))*Fractions!$B$3*F8^3/((Constants!$B$12-1)*Constants!$B$2) | I8: =IF(E8<=0,0,IF(E8/Fractions!$F$4<Constants!$B$10,0.002*(E8/Fractions!$F$4)^7.5,14*(1-0.894/SQRT(E8/Fractions!$F$4))^4.5))*Fractions!$B$4*F8^3/((Constants!$B$12-1)*Constants!$B$2) | J8: =IF(E8<=0,0,IF(E8/Fractions!$F$5<Constants!$B$10,0.002*(E8/Fractions!$F$5)^7.5,14*(1-0.894/SQRT(E8/Fractions!$F$5))^4.5))*Fractions!$B$5*F8^3/((Constants!$B$12-1)*Constants!$B$2) | K8: =IF(E8<=0,0,IF(E8/Fractions!$F$6<Constants!$B$10,0.002*(E8/Fractions!$F$6)^7.5,14*(1-0.894/SQRT(E8/Fractions!$F$6))^4.5))*Fractions!$B$6*F8^3/((Constants!$B$12-1)*Constants!$B$2) | L8: =SUM(G8:K8) | M8: =YEAR(A8)
A9: 40543 | B9: 6.5 | C9: =IF(MONTH(A9)>=10,YEAR(A9)+1,YEAR(A9)) | D9: =B9/(Constants!$B$6*Constants!$B$5) | E9: =Constants!$B$3*Constants!$B$2*Constants!$B$7^2*D9^2/Constants!$B$5^(1/3) | F9: =SQRT(E9/Constants!$B$3) | G9: =IF(E9<=0,0,IF(E9/Fractions!$F$2<Constants!$B$10,0.002*(E9/Fractions!$F$2)^7.5,14*(1-0.894/SQRT(E9/Fractions!$F$2))^4.5))*Fractions!$B$2*F9^3/((Constants!$B$12-1)*Constants!$B$2) | H9: =IF(E9<=0,0,IF(E9/Fractions!$F$3<Constants!$B$10,0.002*(E9/Fractions!$F$3)^7.5,14*(1-0.894/SQRT(E9/Fractions!$F$3))^4.5))*Fractions!$B$3*F9^3/((Constants!$B$12-1)*Constants!$B$2) | I9: =IF(E9<=0,0,IF(E9/Fractions!$F$4<Constants!$B$10,0.002*(E9/Fractions!$F$4)^7.5,14*(1-0.894/SQRT(E9/Fractions!$F$4))^4.5))*Fractions!$B$4*F9^3/((Constants!$B$12-1)*Constants!$B$2) | J9: =IF(E9<=0,0,IF(E9/Fractions!$F$5<Constants!$B$10,0.002*(E9/Fractions!$F$5)^7.5,14*(1-0.894/SQRT(E9/Fractions!$F$5))^4.5))*Fractions!$B$5*F9^3/((Constants!$B$12-1)*Constants!$B$2) | K9: =IF(E9<=0,0,IF(E9/Fractions!$F$6<Constants!$B$10,0.002*(E9/Fractions!$F$6)^7.5,14*(1-0.894/SQRT(E9/Fractions!$F$6))^4.5))*Fractions!$B$6*F9^3/((Constants!$B$12-1)*Constants!$B$2) | L9: =SUM(G9:K9) | M9: =YEAR(A9)
