Workbook

Sheet B3.3 cases
A1: Case | B1: Description | C1: Hbed (m) | D1: Hmin given (m, blank = shape class) | E1: Hmax (m) | F1: Hcrest (m) | G1: Vactive (hm3) | H1: Vmax (hm3) | I1: Shape class | J1: Shape-class exponent | K1: Vdead (hm3) = Vmax - Vactive | L1: m = ln(Vdead/Vmax) / ln((Hmin-Hbed)/(Hmax-Hbed)), or the class exponent | M1: Hmin used (m) = Hbed + (Hmax-Hbed) (Vdead/Vmax)^(1/m) | N1: A(Hmax) (km2) = m Vmax / (Hmax-Hbed) | Q1: Shape class | R1: Exponent m
A2: 1 | B2: Kavsakkaya sample, foothill | C2: 1063 | E2: 1122.3 | F2: 1124 | G2: 74.1 | H2: 80.8 | I2: foothill | J2: =IF(I2="","",VLOOKUP(I2,$Q$2:$R$5,2,FALSE)) | K2: =H2-G2 | L2: =IF(D2="",J2,LN(K2/H2)/LN((D2-C2)/(E2-C2))) | M2: =C2+(E2-C2)*(K2/H2)^(1/L2) | N2: =L2*H2/(E2-C2) | Q2: gorge | R2: 1.25
A3: 2 | B3: Cubuk 1 sample, hill | C3: 888 | E3: 907.6 | F3: 908.6 | G3: 5.28 | H3: 5.6 | I3: hill | J3: =IF(I3="","",VLOOKUP(I3,$Q$2:$R$5,2,FALSE)) | K3: =H3-G3 | L3: =IF(D3="",J3,LN(K3/H3)/LN((D3-C3)/(E3-C3))) | M3: =C3+(E3-C3)*(K3/H3)^(1/L3) | N3: =L3*H3/(E3-C3) | Q3: hill | R3: 2
A4: 3 | B4: Cubuk 2 sample, hill (OI-01) | C4: 1110 | E4: 1115.3 | F4: 1117 | G4: 22 | H4: 22.4 | I4: hill | J4: =IF(I4="","",VLOOKUP(I4,$Q$2:$R$5,2,FALSE)) | K4: =H4-G4 | L4: =IF(D4="",J4,LN(K4/H4)/LN((D4-C4)/(E4-C4))) | M4: =C4+(E4-C4)*(K4/H4)^(1/L4) | N4: =L4*H4/(E4-C4) | Q4: foothill | R4: 3
A5: 4 | B5: Kavsakkaya sample, Hmin given | C5: 1063 | D5: 1090 | E5: 1122.3 | F5: 1124 | G5: 74.1 | H5: 80.8 | J5: =IF(I5="","",VLOOKUP(I5,$Q$2:$R$5,2,FALSE)) | K5: =H5-G5 | L5: =IF(D5="",J5,LN(K5/H5)/LN((D5-C5)/(E5-C5))) | M5: =C5+(E5-C5)*(K5/H5)^(1/L5) | N5: =L5*H5/(E5-C5) | Q5: lake | R5: 4
A6: 5 | B6: Cubuk 1 sample, Hmin given | C6: 888 | D6: 895 | E6: 907.6 | F6: 908.6 | G6: 5.28 | H6: 5.6 | J6: =IF(I6="","",VLOOKUP(I6,$Q$2:$R$5,2,FALSE)) | K6: =H6-G6 | L6: =IF(D6="",J6,LN(K6/H6)/LN((D6-C6)/(E6-C6))) | M6: =C6+(E6-C6)*(K6/H6)^(1/L6) | N6: =L6*H6/(E6-C6)
A7: 6 | B7: Round numbers, Hmin gives m = 2 | C7: 100 | D7: 125 | E7: 150 | F7: 155 | G7: 75 | H7: 100 | J7: =IF(I7="","",VLOOKUP(I7,$Q$2:$R$5,2,FALSE)) | K7: =H7-G7 | L7: =IF(D7="",J7,LN(K7/H7)/LN((D7-C7)/(E7-C7))) | M7: =C7+(E7-C7)*(K7/H7)^(1/L7) | N7: =L7*H7/(E7-C7)
A8: 7 | B8: Round numbers, gorge | C8: 0 | E8: 10 | F8: 12 | G8: 90 | H8: 100 | I8: gorge | J8: =IF(I8="","",VLOOKUP(I8,$Q$2:$R$5,2,FALSE)) | K8: =H8-G8 | L8: =IF(D8="",J8,LN(K8/H8)/LN((D8-C8)/(E8-C8))) | M8: =C8+(E8-C8)*(K8/H8)^(1/L8) | N8: =L8*H8/(E8-C8)
A9: 8 | B9: Round numbers, lake | C9: 0 | E9: 10 | F9: 12 | G9: 90 | H9: 100 | I9: lake | J9: =IF(I9="","",VLOOKUP(I9,$Q$2:$R$5,2,FALSE)) | K9: =H9-G9 | L9: =IF(D9="",J9,LN(K9/H9)/LN((D9-C9)/(E9-C9))) | M9: =C9+(E9-C9)*(K9/H9)^(1/L9) | N9: =L9*H9/(E9-C9)

Sheet B3.3 points
A1: Case | B1: Point | C1: H (m) | D1: V (hm3) = Vmax x^m, x = (H-Hbed)/(Hmax-Hbed) | E1: A (km2) = m Vmax / (Hmax-Hbed) x^(m-1) | F1: H back from V (m) = Hbed + (Hmax-Hbed) (V/Vmax)^(1/m)
A2: 1 | B2: Hbed | C2: ='B3.3 cases'!$C$2 | D2: ='B3.3 cases'!$H$2*((C2-'B3.3 cases'!$C$2)/('B3.3 cases'!$E$2-'B3.3 cases'!$C$2))^'B3.3 cases'!$L$2 | E2: ='B3.3 cases'!$L$2*'B3.3 cases'!$H$2/('B3.3 cases'!$E$2-'B3.3 cases'!$C$2)*((C2-'B3.3 cases'!$C$2)/('B3.3 cases'!$E$2-'B3.3 cases'!$C$2))^('B3.3 cases'!$L$2-1) | F2: ='B3.3 cases'!$C$2+('B3.3 cases'!$E$2-'B3.3 cases'!$C$2)*(D2/'B3.3 cases'!$H$2)^(1/'B3.3 cases'!$L$2)
A3: 1 | B3: Hmin | C3: ='B3.3 cases'!$M$2 | D3: ='B3.3 cases'!$H$2*((C3-'B3.3 cases'!$C$2)/('B3.3 cases'!$E$2-'B3.3 cases'!$C$2))^'B3.3 cases'!$L$2 | E3: ='B3.3 cases'!$L$2*'B3.3 cases'!$H$2/('B3.3 cases'!$E$2-'B3.3 cases'!$C$2)*((C3-'B3.3 cases'!$C$2)/('B3.3 cases'!$E$2-'B3.3 cases'!$C$2))^('B3.3 cases'!$L$2-1) | F3: ='B3.3 cases'!$C$2+('B3.3 cases'!$E$2-'B3.3 cases'!$C$2)*(D3/'B3.3 cases'!$H$2)^(1/'B3.3 cases'!$L$2)
A4: 1 | B4: Hmid | C4: =('B3.3 cases'!$C$2+'B3.3 cases'!$E$2)/2 | D4: ='B3.3 cases'!$H$2*((C4-'B3.3 cases'!$C$2)/('B3.3 cases'!$E$2-'B3.3 cases'!$C$2))^'B3.3 cases'!$L$2 | E4: ='B3.3 cases'!$L$2*'B3.3 cases'!$H$2/('B3.3 cases'!$E$2-'B3.3 cases'!$C$2)*((C4-'B3.3 cases'!$C$2)/('B3.3 cases'!$E$2-'B3.3 cases'!$C$2))^('B3.3 cases'!$L$2-1) | F4: ='B3.3 cases'!$C$2+('B3.3 cases'!$E$2-'B3.3 cases'!$C$2)*(D4/'B3.3 cases'!$H$2)^(1/'B3.3 cases'!$L$2)
A5: 1 | B5: Hmax | C5: ='B3.3 cases'!$E$2 | D5: ='B3.3 cases'!$H$2*((C5-'B3.3 cases'!$C$2)/('B3.3 cases'!$E$2-'B3.3 cases'!$C$2))^'B3.3 cases'!$L$2 | E5: ='B3.3 cases'!$L$2*'B3.3 cases'!$H$2/('B3.3 cases'!$E$2-'B3.3 cases'!$C$2)*((C5-'B3.3 cases'!$C$2)/('B3.3 cases'!$E$2-'B3.3 cases'!$C$2))^('B3.3 cases'!$L$2-1) | F5: ='B3.3 cases'!$C$2+('B3.3 cases'!$E$2-'B3.3 cases'!$C$2)*(D5/'B3.3 cases'!$H$2)^(1/'B3.3 cases'!$L$2)
A6: 1 | B6: Hcrest | C6: ='B3.3 cases'!$F$2 | D6: ='B3.3 cases'!$H$2*((C6-'B3.3 cases'!$C$2)/('B3.3 cases'!$E$2-'B3.3 cases'!$C$2))^'B3.3 cases'!$L$2 | E6: ='B3.3 cases'!$L$2*'B3.3 cases'!$H$2/('B3.3 cases'!$E$2-'B3.3 cases'!$C$2)*((C6-'B3.3 cases'!$C$2)/('B3.3 cases'!$E$2-'B3.3 cases'!$C$2))^('B3.3 cases'!$L$2-1) | F6: ='B3.3 cases'!$C$2+('B3.3 cases'!$E$2-'B3.3 cases'!$C$2)*(D6/'B3.3 cases'!$H$2)^(1/'B3.3 cases'!$L$2)
A7: 2 | B7: Hbed | C7: ='B3.3 cases'!$C$3 | D7: ='B3.3 cases'!$H$3*((C7-'B3.3 cases'!$C$3)/('B3.3 cases'!$E$3-'B3.3 cases'!$C$3))^'B3.3 cases'!$L$3 | E7: ='B3.3 cases'!$L$3*'B3.3 cases'!$H$3/('B3.3 cases'!$E$3-'B3.3 cases'!$C$3)*((C7-'B3.3 cases'!$C$3)/('B3.3 cases'!$E$3-'B3.3 cases'!$C$3))^('B3.3 cases'!$L$3-1) | F7: ='B3.3 cases'!$C$3+('B3.3 cases'!$E$3-'B3.3 cases'!$C$3)*(D7/'B3.3 cases'!$H$3)^(1/'B3.3 cases'!$L$3)
A8: 2 | B8: Hmin | C8: ='B3.3 cases'!$M$3 | D8: ='B3.3 cases'!$H$3*((C8-'B3.3 cases'!$C$3)/('B3.3 cases'!$E$3-'B3.3 cases'!$C$3))^'B3.3 cases'!$L$3 | E8: ='B3.3 cases'!$L$3*'B3.3 cases'!$H$3/('B3.3 cases'!$E$3-'B3.3 cases'!$C$3)*((C8-'B3.3 cases'!$C$3)/('B3.3 cases'!$E$3-'B3.3 cases'!$C$3))^('B3.3 cases'!$L$3-1) | F8: ='B3.3 cases'!$C$3+('B3.3 cases'!$E$3-'B3.3 cases'!$C$3)*(D8/'B3.3 cases'!$H$3)^(1/'B3.3 cases'!$L$3)
A9: 2 | B9: Hmid | C9: =('B3.3 cases'!$C$3+'B3.3 cases'!$E$3)/2 | D9: ='B3.3 cases'!$H$3*((C9-'B3.3 cases'!$C$3)/('B3.3 cases'!$E$3-'B3.3 cases'!$C$3))^'B3.3 cases'!$L$3 | E9: ='B3.3 cases'!$L$3*'B3.3 cases'!$H$3/('B3.3 cases'!$E$3-'B3.3 cases'!$C$3)*((C9-'B3.3 cases'!$C$3)/('B3.3 cases'!$E$3-'B3.3 cases'!$C$3))^('B3.3 cases'!$L$3-1) | F9: ='B3.3 cases'!$C$3+('B3.3 cases'!$E$3-'B3.3 cases'!$C$3)*(D9/'B3.3 cases'!$H$3)^(1/'B3.3 cases'!$L$3)
A10: 2 | B10: Hmax | C10: ='B3.3 cases'!$E$3 | D10: ='B3.3 cases'!$H$3*((C10-'B3.3 cases'!$C$3)/('B3.3 cases'!$E$3-'B3.3 cases'!$C$3))^'B3.3 cases'!$L$3 | E10: ='B3.3 cases'!$L$3*'B3.3 cases'!$H$3/('B3.3 cases'!$E$3-'B3.3 cases'!$C$3)*((C10-'B3.3 cases'!$C$3)/('B3.3 cases'!$E$3-'B3.3 cases'!$C$3))^('B3.3 cases'!$L$3-1) | F10: ='B3.3 cases'!$C$3+('B3.3 cases'!$E$3-'B3.3 cases'!$C$3)*(D10/'B3.3 cases'!$H$3)^(1/'B3.3 cases'!$L$3)
A11: 2 | B11: Hcrest | C11: ='B3.3 cases'!$F$3 | D11: ='B3.3 cases'!$H$3*((C11-'B3.3 cases'!$C$3)/('B3.3 cases'!$E$3-'B3.3 cases'!$C$3))^'B3.3 cases'!$L$3 | E11: ='B3.3 cases'!$L$3*'B3.3 cases'!$H$3/('B3.3 cases'!$E$3-'B3.3 cases'!$C$3)*((C11-'B3.3 cases'!$C$3)/('B3.3 cases'!$E$3-'B3.3 cases'!$C$3))^('B3.3 cases'!$L$3-1) | F11: ='B3.3 cases'!$C$3+('B3.3 cases'!$E$3-'B3.3 cases'!$C$3)*(D11/'B3.3 cases'!$H$3)^(1/'B3.3 cases'!$L$3)
A12: 3 | B12: Hbed | C12: ='B3.3 cases'!$C$4 | D12: ='B3.3 cases'!$H$4*((C12-'B3.3 cases'!$C$4)/('B3.3 cases'!$E$4-'B3.3 cases'!$C$4))^'B3.3 cases'!$L$4 | E12: ='B3.3 cases'!$L$4*'B3.3 cases'!$H$4/('B3.3 cases'!$E$4-'B3.3 cases'!$C$4)*((C12-'B3.3 cases'!$C$4)/('B3.3 cases'!$E$4-'B3.3 cases'!$C$4))^('B3.3 cases'!$L$4-1) | F12: ='B3.3 cases'!$C$4+('B3.3 cases'!$E$4-'B3.3 cases'!$C$4)*(D12/'B3.3 cases'!$H$4)^(1/'B3.3 cases'!$L$4)
A13: 3 | B13: Hmin | C13: ='B3.3 cases'!$M$4 | D13: ='B3.3 cases'!$H$4*((C13-'B3.3 cases'!$C$4)/('B3.3 cases'!$E$4-'B3.3 cases'!$C$4))^'B3.3 cases'!$L$4 | E13: ='B3.3 cases'!$L$4*'B3.3 cases'!$H$4/('B3.3 cases'!$E$4-'B3.3 cases'!$C$4)*((C13-'B3.3 cases'!$C$4)/('B3.3 cases'!$E$4-'B3.3 cases'!$C$4))^('B3.3 cases'!$L$4-1) | F13: ='B3.3 cases'!$C$4+('B3.3 cases'!$E$4-'B3.3 cases'!$C$4)*(D13/'B3.3 cases'!$H$4)^(1/'B3.3 cases'!$L$4)
A14: 3 | B14: Hmid | C14: =('B3.3 cases'!$C$4+'B3.3 cases'!$E$4)/2 | D14: ='B3.3 cases'!$H$4*((C14-'B3.3 cases'!$C$4)/('B3.3 cases'!$E$4-'B3.3 cases'!$C$4))^'B3.3 cases'!$L$4 | E14: ='B3.3 cases'!$L$4*'B3.3 cases'!$H$4/('B3.3 cases'!$E$4-'B3.3 cases'!$C$4)*((C14-'B3.3 cases'!$C$4)/('B3.3 cases'!$E$4-'B3.3 cases'!$C$4))^('B3.3 cases'!$L$4-1) | F14: ='B3.3 cases'!$C$4+('B3.3 cases'!$E$4-'B3.3 cases'!$C$4)*(D14/'B3.3 cases'!$H$4)^(1/'B3.3 cases'!$L$4)
A15: 3 | B15: Hmax | C15: ='B3.3 cases'!$E$4 | D15: ='B3.3 cases'!$H$4*((C15-'B3.3 cases'!$C$4)/('B3.3 cases'!$E$4-'B3.3 cases'!$C$4))^'B3.3 cases'!$L$4 | E15: ='B3.3 cases'!$L$4*'B3.3 cases'!$H$4/('B3.3 cases'!$E$4-'B3.3 cases'!$C$4)*((C15-'B3.3 cases'!$C$4)/('B3.3 cases'!$E$4-'B3.3 cases'!$C$4))^('B3.3 cases'!$L$4-1) | F15: ='B3.3 cases'!$C$4+('B3.3 cases'!$E$4-'B3.3 cases'!$C$4)*(D15/'B3.3 cases'!$H$4)^(1/'B3.3 cases'!$L$4)
A16: 3 | B16: Hcrest | C16: ='B3.3 cases'!$F$4 | D16: ='B3.3 cases'!$H$4*((C16-'B3.3 cases'!$C$4)/('B3.3 cases'!$E$4-'B3.3 cases'!$C$4))^'B3.3 cases'!$L$4 | E16: ='B3.3 cases'!$L$4*'B3.3 cases'!$H$4/('B3.3 cases'!$E$4-'B3.3 cases'!$C$4)*((C16-'B3.3 cases'!$C$4)/('B3.3 cases'!$E$4-'B3.3 cases'!$C$4))^('B3.3 cases'!$L$4-1) | F16: ='B3.3 cases'!$C$4+('B3.3 cases'!$E$4-'B3.3 cases'!$C$4)*(D16/'B3.3 cases'!$H$4)^(1/'B3.3 cases'!$L$4)
A17: 4 | B17: Hbed | C17: ='B3.3 cases'!$C$5 | D17: ='B3.3 cases'!$H$5*((C17-'B3.3 cases'!$C$5)/('B3.3 cases'!$E$5-'B3.3 cases'!$C$5))^'B3.3 cases'!$L$5 | E17: ='B3.3 cases'!$L$5*'B3.3 cases'!$H$5/('B3.3 cases'!$E$5-'B3.3 cases'!$C$5)*((C17-'B3.3 cases'!$C$5)/('B3.3 cases'!$E$5-'B3.3 cases'!$C$5))^('B3.3 cases'!$L$5-1) | F17: ='B3.3 cases'!$C$5+('B3.3 cases'!$E$5-'B3.3 cases'!$C$5)*(D17/'B3.3 cases'!$H$5)^(1/'B3.3 cases'!$L$5)
A18: 4 | B18: Hmin | C18: ='B3.3 cases'!$M$5 | D18: ='B3.3 cases'!$H$5*((C18-'B3.3 cases'!$C$5)/('B3.3 cases'!$E$5-'B3.3 cases'!$C$5))^'B3.3 cases'!$L$5 | E18: ='B3.3 cases'!$L$5*'B3.3 cases'!$H$5/('B3.3 cases'!$E$5-'B3.3 cases'!$C$5)*((C18-'B3.3 cases'!$C$5)/('B3.3 cases'!$E$5-'B3.3 cases'!$C$5))^('B3.3 cases'!$L$5-1) | F18: ='B3.3 cases'!$C$5+('B3.3 cases'!$E$5-'B3.3 cases'!$C$5)*(D18/'B3.3 cases'!$H$5)^(1/'B3.3 cases'!$L$5)
A19: 4 | B19: Hmid | C19: =('B3.3 cases'!$C$5+'B3.3 cases'!$E$5)/2 | D19: ='B3.3 cases'!$H$5*((C19-'B3.3 cases'!$C$5)/('B3.3 cases'!$E$5-'B3.3 cases'!$C$5))^'B3.3 cases'!$L$5 | E19: ='B3.3 cases'!$L$5*'B3.3 cases'!$H$5/('B3.3 cases'!$E$5-'B3.3 cases'!$C$5)*((C19-'B3.3 cases'!$C$5)/('B3.3 cases'!$E$5-'B3.3 cases'!$C$5))^('B3.3 cases'!$L$5-1) | F19: ='B3.3 cases'!$C$5+('B3.3 cases'!$E$5-'B3.3 cases'!$C$5)*(D19/'B3.3 cases'!$H$5)^(1/'B3.3 cases'!$L$5)
A20: 4 | B20: Hmax | C20: ='B3.3 cases'!$E$5 | D20: ='B3.3 cases'!$H$5*((C20-'B3.3 cases'!$C$5)/('B3.3 cases'!$E$5-'B3.3 cases'!$C$5))^'B3.3 cases'!$L$5 | E20: ='B3.3 cases'!$L$5*'B3.3 cases'!$H$5/('B3.3 cases'!$E$5-'B3.3 cases'!$C$5)*((C20-'B3.3 cases'!$C$5)/('B3.3 cases'!$E$5-'B3.3 cases'!$C$5))^('B3.3 cases'!$L$5-1) | F20: ='B3.3 cases'!$C$5+('B3.3 cases'!$E$5-'B3.3 cases'!$C$5)*(D20/'B3.3 cases'!$H$5)^(1/'B3.3 cases'!$L$5)
A21: 4 | B21: Hcrest | C21: ='B3.3 cases'!$F$5 | D21: ='B3.3 cases'!$H$5*((C21-'B3.3 cases'!$C$5)/('B3.3 cases'!$E$5-'B3.3 cases'!$C$5))^'B3.3 cases'!$L$5 | E21: ='B3.3 cases'!$L$5*'B3.3 cases'!$H$5/('B3.3 cases'!$E$5-'B3.3 cases'!$C$5)*((C21-'B3.3 cases'!$C$5)/('B3.3 cases'!$E$5-'B3.3 cases'!$C$5))^('B3.3 cases'!$L$5-1) | F21: ='B3.3 cases'!$C$5+('B3.3 cases'!$E$5-'B3.3 cases'!$C$5)*(D21/'B3.3 cases'!$H$5)^(1/'B3.3 cases'!$L$5)
A22: 5 | B22: Hbed | C22: ='B3.3 cases'!$C$6 | D22: ='B3.3 cases'!$H$6*((C22-'B3.3 cases'!$C$6)/('B3.3 cases'!$E$6-'B3.3 cases'!$C$6))^'B3.3 cases'!$L$6 | E22: ='B3.3 cases'!$L$6*'B3.3 cases'!$H$6/('B3.3 cases'!$E$6-'B3.3 cases'!$C$6)*((C22-'B3.3 cases'!$C$6)/('B3.3 cases'!$E$6-'B3.3 cases'!$C$6))^('B3.3 cases'!$L$6-1) | F22: ='B3.3 cases'!$C$6+('B3.3 cases'!$E$6-'B3.3 cases'!$C$6)*(D22/'B3.3 cases'!$H$6)^(1/'B3.3 cases'!$L$6)
A23: 5 | B23: Hmin | C23: ='B3.3 cases'!$M$6 | D23: ='B3.3 cases'!$H$6*((C23-'B3.3 cases'!$C$6)/('B3.3 cases'!$E$6-'B3.3 cases'!$C$6))^'B3.3 cases'!$L$6 | E23: ='B3.3 cases'!$L$6*'B3.3 cases'!$H$6/('B3.3 cases'!$E$6-'B3.3 cases'!$C$6)*((C23-'B3.3 cases'!$C$6)/('B3.3 cases'!$E$6-'B3.3 cases'!$C$6))^('B3.3 cases'!$L$6-1) | F23: ='B3.3 cases'!$C$6+('B3.3 cases'!$E$6-'B3.3 cases'!$C$6)*(D23/'B3.3 cases'!$H$6)^(1/'B3.3 cases'!$L$6)
A24: 5 | B24: Hmid | C24: =('B3.3 cases'!$C$6+'B3.3 cases'!$E$6)/2 | D24: ='B3.3 cases'!$H$6*((C24-'B3.3 cases'!$C$6)/('B3.3 cases'!$E$6-'B3.3 cases'!$C$6))^'B3.3 cases'!$L$6 | E24: ='B3.3 cases'!$L$6*'B3.3 cases'!$H$6/('B3.3 cases'!$E$6-'B3.3 cases'!$C$6)*((C24-'B3.3 cases'!$C$6)/('B3.3 cases'!$E$6-'B3.3 cases'!$C$6))^('B3.3 cases'!$L$6-1) | F24: ='B3.3 cases'!$C$6+('B3.3 cases'!$E$6-'B3.3 cases'!$C$6)*(D24/'B3.3 cases'!$H$6)^(1/'B3.3 cases'!$L$6)
A25: 5 | B25: Hmax | C25: ='B3.3 cases'!$E$6 | D25: ='B3.3 cases'!$H$6*((C25-'B3.3 cases'!$C$6)/('B3.3 cases'!$E$6-'B3.3 cases'!$C$6))^'B3.3 cases'!$L$6 | E25: ='B3.3 cases'!$L$6*'B3.3 cases'!$H$6/('B3.3 cases'!$E$6-'B3.3 cases'!$C$6)*((C25-'B3.3 cases'!$C$6)/('B3.3 cases'!$E$6-'B3.3 cases'!$C$6))^('B3.3 cases'!$L$6-1) | F25: ='B3.3 cases'!$C$6+('B3.3 cases'!$E$6-'B3.3 cases'!$C$6)*(D25/'B3.3 cases'!$H$6)^(1/'B3.3 cases'!$L$6)
A26: 5 | B26: Hcrest | C26: ='B3.3 cases'!$F$6 | D26: ='B3.3 cases'!$H$6*((C26-'B3.3 cases'!$C$6)/('B3.3 cases'!$E$6-'B3.3 cases'!$C$6))^'B3.3 cases'!$L$6 | E26: ='B3.3 cases'!$L$6*'B3.3 cases'!$H$6/('B3.3 cases'!$E$6-'B3.3 cases'!$C$6)*((C26-'B3.3 cases'!$C$6)/('B3.3 cases'!$E$6-'B3.3 cases'!$C$6))^('B3.3 cases'!$L$6-1) | F26: ='B3.3 cases'!$C$6+('B3.3 cases'!$E$6-'B3.3 cases'!$C$6)*(D26/'B3.3 cases'!$H$6)^(1/'B3.3 cases'!$L$6)
A27: 6 | B27: Hbed | C27: ='B3.3 cases'!$C$7 | D27: ='B3.3 cases'!$H$7*((C27-'B3.3 cases'!$C$7)/('B3.3 cases'!$E$7-'B3.3 cases'!$C$7))^'B3.3 cases'!$L$7 | E27: ='B3.3 cases'!$L$7*'B3.3 cases'!$H$7/('B3.3 cases'!$E$7-'B3.3 cases'!$C$7)*((C27-'B3.3 cases'!$C$7)/('B3.3 cases'!$E$7-'B3.3 cases'!$C$7))^('B3.3 cases'!$L$7-1) | F27: ='B3.3 cases'!$C$7+('B3.3 cases'!$E$7-'B3.3 cases'!$C$7)*(D27/'B3.3 cases'!$H$7)^(1/'B3.3 cases'!$L$7)
A28: 6 | B28: Hmin | C28: ='B3.3 cases'!$M$7 | D28: ='B3.3 cases'!$H$7*((C28-'B3.3 cases'!$C$7)/('B3.3 cases'!$E$7-'B3.3 cases'!$C$7))^'B3.3 cases'!$L$7 | E28: ='B3.3 cases'!$L$7*'B3.3 cases'!$H$7/('B3.3 cases'!$E$7-'B3.3 cases'!$C$7)*((C28-'B3.3 cases'!$C$7)/('B3.3 cases'!$E$7-'B3.3 cases'!$C$7))^('B3.3 cases'!$L$7-1) | F28: ='B3.3 cases'!$C$7+('B3.3 cases'!$E$7-'B3.3 cases'!$C$7)*(D28/'B3.3 cases'!$H$7)^(1/'B3.3 cases'!$L$7)
A29: 6 | B29: Hmid | C29: =('B3.3 cases'!$C$7+'B3.3 cases'!$E$7)/2 | D29: ='B3.3 cases'!$H$7*((C29-'B3.3 cases'!$C$7)/('B3.3 cases'!$E$7-'B3.3 cases'!$C$7))^'B3.3 cases'!$L$7 | E29: ='B3.3 cases'!$L$7*'B3.3 cases'!$H$7/('B3.3 cases'!$E$7-'B3.3 cases'!$C$7)*((C29-'B3.3 cases'!$C$7)/('B3.3 cases'!$E$7-'B3.3 cases'!$C$7))^('B3.3 cases'!$L$7-1) | F29: ='B3.3 cases'!$C$7+('B3.3 cases'!$E$7-'B3.3 cases'!$C$7)*(D29/'B3.3 cases'!$H$7)^(1/'B3.3 cases'!$L$7)
A30: 6 | B30: Hmax | C30: ='B3.3 cases'!$E$7 | D30: ='B3.3 cases'!$H$7*((C30-'B3.3 cases'!$C$7)/('B3.3 cases'!$E$7-'B3.3 cases'!$C$7))^'B3.3 cases'!$L$7 | E30: ='B3.3 cases'!$L$7*'B3.3 cases'!$H$7/('B3.3 cases'!$E$7-'B3.3 cases'!$C$7)*((C30-'B3.3 cases'!$C$7)/('B3.3 cases'!$E$7-'B3.3 cases'!$C$7))^('B3.3 cases'!$L$7-1) | F30: ='B3.3 cases'!$C$7+('B3.3 cases'!$E$7-'B3.3 cases'!$C$7)*(D30/'B3.3 cases'!$H$7)^(1/'B3.3 cases'!$L$7)
A31: 6 | B31: Hcrest | C31: ='B3.3 cases'!$F$7 | D31: ='B3.3 cases'!$H$7*((C31-'B3.3 cases'!$C$7)/('B3.3 cases'!$E$7-'B3.3 cases'!$C$7))^'B3.3 cases'!$L$7 | E31: ='B3.3 cases'!$L$7*'B3.3 cases'!$H$7/('B3.3 cases'!$E$7-'B3.3 cases'!$C$7)*((C31-'B3.3 cases'!$C$7)/('B3.3 cases'!$E$7-'B3.3 cases'!$C$7))^('B3.3 cases'!$L$7-1) | F31: ='B3.3 cases'!$C$7+('B3.3 cases'!$E$7-'B3.3 cases'!$C$7)*(D31/'B3.3 cases'!$H$7)^(1/'B3.3 cases'!$L$7)
A32: 7 | B32: Hbed | C32: ='B3.3 cases'!$C$8 | D32: ='B3.3 cases'!$H$8*((C32-'B3.3 cases'!$C$8)/('B3.3 cases'!$E$8-'B3.3 cases'!$C$8))^'B3.3 cases'!$L$8 | E32: ='B3.3 cases'!$L$8*'B3.3 cases'!$H$8/('B3.3 cases'!$E$8-'B3.3 cases'!$C$8)*((C32-'B3.3 cases'!$C$8)/('B3.3 cases'!$E$8-'B3.3 cases'!$C$8))^('B3.3 cases'!$L$8-1) | F32: ='B3.3 cases'!$C$8+('B3.3 cases'!$E$8-'B3.3 cases'!$C$8)*(D32/'B3.3 cases'!$H$8)^(1/'B3.3 cases'!$L$8)
A33: 7 | B33: Hmin | C33: ='B3.3 cases'!$M$8 | D33: ='B3.3 cases'!$H$8*((C33-'B3.3 cases'!$C$8)/('B3.3 cases'!$E$8-'B3.3 cases'!$C$8))^'B3.3 cases'!$L$8 | E33: ='B3.3 cases'!$L$8*'B3.3 cases'!$H$8/('B3.3 cases'!$E$8-'B3.3 cases'!$C$8)*((C33-'B3.3 cases'!$C$8)/('B3.3 cases'!$E$8-'B3.3 cases'!$C$8))^('B3.3 cases'!$L$8-1) | F33: ='B3.3 cases'!$C$8+('B3.3 cases'!$E$8-'B3.3 cases'!$C$8)*(D33/'B3.3 cases'!$H$8)^(1/'B3.3 cases'!$L$8)
A34: 7 | B34: Hmid | C34: =('B3.3 cases'!$C$8+'B3.3 cases'!$E$8)/2 | D34: ='B3.3 cases'!$H$8*((C34-'B3.3 cases'!$C$8)/('B3.3 cases'!$E$8-'B3.3 cases'!$C$8))^'B3.3 cases'!$L$8 | E34: ='B3.3 cases'!$L$8*'B3.3 cases'!$H$8/('B3.3 cases'!$E$8-'B3.3 cases'!$C$8)*((C34-'B3.3 cases'!$C$8)/('B3.3 cases'!$E$8-'B3.3 cases'!$C$8))^('B3.3 cases'!$L$8-1) | F34: ='B3.3 cases'!$C$8+('B3.3 cases'!$E$8-'B3.3 cases'!$C$8)*(D34/'B3.3 cases'!$H$8)^(1/'B3.3 cases'!$L$8)
A35: 7 | B35: Hmax | C35: ='B3.3 cases'!$E$8 | D35: ='B3.3 cases'!$H$8*((C35-'B3.3 cases'!$C$8)/('B3.3 cases'!$E$8-'B3.3 cases'!$C$8))^'B3.3 cases'!$L$8 | E35: ='B3.3 cases'!$L$8*'B3.3 cases'!$H$8/('B3.3 cases'!$E$8-'B3.3 cases'!$C$8)*((C35-'B3.3 cases'!$C$8)/('B3.3 cases'!$E$8-'B3.3 cases'!$C$8))^('B3.3 cases'!$L$8-1) | F35: ='B3.3 cases'!$C$8+('B3.3 cases'!$E$8-'B3.3 cases'!$C$8)*(D35/'B3.3 cases'!$H$8)^(1/'B3.3 cases'!$L$8)
A36: 7 | B36: Hcrest | C36: ='B3.3 cases'!$F$8 | D36: ='B3.3 cases'!$H$8*((C36-'B3.3 cases'!$C$8)/('B3.3 cases'!$E$8-'B3.3 cases'!$C$8))^'B3.3 cases'!$L$8 | E36: ='B3.3 cases'!$L$8*'B3.3 cases'!$H$8/('B3.3 cases'!$E$8-'B3.3 cases'!$C$8)*((C36-'B3.3 cases'!$C$8)/('B3.3 cases'!$E$8-'B3.3 cases'!$C$8))^('B3.3 cases'!$L$8-1) | F36: ='B3.3 cases'!$C$8+('B3.3 cases'!$E$8-'B3.3 cases'!$C$8)*(D36/'B3.3 cases'!$H$8)^(1/'B3.3 cases'!$L$8)
A37: 8 | B37: Hbed | C37: ='B3.3 cases'!$C$9 | D37: ='B3.3 cases'!$H$9*((C37-'B3.3 cases'!$C$9)/('B3.3 cases'!$E$9-'B3.3 cases'!$C$9))^'B3.3 cases'!$L$9 | E37: ='B3.3 cases'!$L$9*'B3.3 cases'!$H$9/('B3.3 cases'!$E$9-'B3.3 cases'!$C$9)*((C37-'B3.3 cases'!$C$9)/('B3.3 cases'!$E$9-'B3.3 cases'!$C$9))^('B3.3 cases'!$L$9-1) | F37: ='B3.3 cases'!$C$9+('B3.3 cases'!$E$9-'B3.3 cases'!$C$9)*(D37/'B3.3 cases'!$H$9)^(1/'B3.3 cases'!$L$9)
A38: 8 | B38: Hmin | C38: ='B3.3 cases'!$M$9 | D38: ='B3.3 cases'!$H$9*((C38-'B3.3 cases'!$C$9)/('B3.3 cases'!$E$9-'B3.3 cases'!$C$9))^'B3.3 cases'!$L$9 | E38: ='B3.3 cases'!$L$9*'B3.3 cases'!$H$9/('B3.3 cases'!$E$9-'B3.3 cases'!$C$9)*((C38-'B3.3 cases'!$C$9)/('B3.3 cases'!$E$9-'B3.3 cases'!$C$9))^('B3.3 cases'!$L$9-1) | F38: ='B3.3 cases'!$C$9+('B3.3 cases'!$E$9-'B3.3 cases'!$C$9)*(D38/'B3.3 cases'!$H$9)^(1/'B3.3 cases'!$L$9)
A39: 8 | B39: Hmid | C39: =('B3.3 cases'!$C$9+'B3.3 cases'!$E$9)/2 | D39: ='B3.3 cases'!$H$9*((C39-'B3.3 cases'!$C$9)/('B3.3 cases'!$E$9-'B3.3 cases'!$C$9))^'B3.3 cases'!$L$9 | E39: ='B3.3 cases'!$L$9*'B3.3 cases'!$H$9/('B3.3 cases'!$E$9-'B3.3 cases'!$C$9)*((C39-'B3.3 cases'!$C$9)/('B3.3 cases'!$E$9-'B3.3 cases'!$C$9))^('B3.3 cases'!$L$9-1) | F39: ='B3.3 cases'!$C$9+('B3.3 cases'!$E$9-'B3.3 cases'!$C$9)*(D39/'B3.3 cases'!$H$9)^(1/'B3.3 cases'!$L$9)
A40: 8 | B40: Hmax | C40: ='B3.3 cases'!$E$9 | D40: ='B3.3 cases'!$H$9*((C40-'B3.3 cases'!$C$9)/('B3.3 cases'!$E$9-'B3.3 cases'!$C$9))^'B3.3 cases'!$L$9 | E40: ='B3.3 cases'!$L$9*'B3.3 cases'!$H$9/('B3.3 cases'!$E$9-'B3.3 cases'!$C$9)*((C40-'B3.3 cases'!$C$9)/('B3.3 cases'!$E$9-'B3.3 cases'!$C$9))^('B3.3 cases'!$L$9-1) | F40: ='B3.3 cases'!$C$9+('B3.3 cases'!$E$9-'B3.3 cases'!$C$9)*(D40/'B3.3 cases'!$H$9)^(1/'B3.3 cases'!$L$9)
...
